Workbook

Sheet README
B2: IT General Controls (ITGC) & User Access Compliance Audit
B3: A self-contained Excel audit workbook demonstrating access-provisioning, deprovisioning, segregation-of-duties, and recertification testing.
B5: Purpose
B6: Simulates a mid-size company's IT access environment (5 business systems, 14 roles, 50 employees, 174 access grants, 118 recertification records) with deliberately embedded ITGC control failures. Every formula in the workbook re-performs a specific audit test an IT/ITGC auditor runs during a SOX or ISO 27001 access review.
B8: Control Objectives Tested
B9: 1) Timely deprovisioning of terminated users (Access_Termination reconciliation) 2) Segregation of Duties (SoD) — no single identity holds two conflicting roles 3) Access provisioned only with documented approval 4) Periodic access recertification completed on schedule, especially for privileged/admin access
B11: How the workbook is wired
B12: HR_Employees, Access_Grants, SoD_Conflict_Matrix and Recertifications are the SOURCE DATA (raw logs, as you would export from HRIS / IAM tooling). Audit_Testing is the AUDIT ENGINE — one row per access grant, entirely formula-driven, that reconciles across the source sheets and raises an exception with a root-cause category. Dashboard aggregates Audit_Testing and Recertifications into exception-rate summaries by Department / System / Reviewer, ready to also drive a native Excel PivotTable (Insert > PivotTable > source = the 'AuditTesting' table) since the underlying range is a proper Excel Table.
B14: Why no VBA / macros / ML
B15: Every flag is a native, auditable Excel formula (INDEX/MATCH, COUNTIFS, nested IF/AND/OR, IFERROR). No macros, no black-box scoring — every number in this workbook can be traced back to a cell you can open and explain line by line, which is exactly what a reviewer or interview panel will ask you to do.
B17: Data disclaimer
B18: All employee names, dates and IDs are synthetically generated (Python, seed=42) for demonstration purposes only. 'Today' for aging/recency calculations is fixed conceptually at 2026-09-18 (TODAY() is used live in formulas, so aging figures will continue to update as you open the file after that date).
B20: Workbook map
B21: README | C21: This page.
B22: HR_Employees | C22: HR master data — hire/termination dates (source of truth for deprovisioning testing).
B23: SoD_Conflict_Matrix | C23: The 6 role-pair conflict rules tested (a real company's SoD ruleset would run to hundreds of rows; this is a representative subset).
B24: Access_Grants | C24: Raw IAM access-provisioning log — every grant of a role to a user, its approver, and its current status.
B25: Recertifications | C25: Periodic access review log — due dates, reviewers, completion dates and outcomes.
B26: Audit_Testing | C26: THE AUDIT ENGINE. One row per access grant with 4 independent formula-driven tests + an overall exception verdict and root-cause category.
B27: Dashboard | C27: Exception-rate summaries by Department, System and Reviewer, plus root-cause mix. Conditional formatting highlights hot spots.
B28: Findings_Memo | C28: Written audit findings memo: condition / criteria / cause / effect / recommendation for each control gap, addressed to the Audit Committee.

Sheet HR_Employees
A1: EmployeeID | B1: Name | C1: Department | D1: JobTitle | E1: HireDate | F1: TerminationDate | G1: Manager | H1: EmploymentStatus
A2: E001 | B2: Sophia Chen | C2: IT Operations | D2: Clerk | E2: 44469 | G2: MGR-02 | H2: =IF(F2="","Active","Terminated") -> Active
A3: E002 | B3: Peter Okafor | C3: HR | D3: Manager | E3: 43596 | F3: 45881 | G3: MGR-04 | H3: =IF(F3="","Active","Terminated") -> Terminated
A4: E003 | B4: Youssef Chen | C4: Procurement | D4: Specialist | E4: 44280 | G4: MGR-09 | H4: =IF(F4="","Active","Terminated") -> Active
A5: E004 | B5: Omar Khan | C5: IT Operations | D5: Clerk | E5: 43492 | G5: MGR-03 | H5: =IF(F5="","Active","Terminated") -> Active
A6: E005 | B6: Olivia Andersson | C6: IT Operations | D6: Analyst | E6: 44102 | G6: MGR-06 | H6: =IF(F6="","Active","Terminated") -> Active
A7: E006 | B7: Fatima Santos | C7: Accounts Payable | D7: Associate | E7: 44936 | G7: MGR-10 | H7: =IF(F7="","Active","Terminated") -> Active
A8: E007 | B8: Wei Petrov | C8: Customer Service | D8: Manager | E8: 45662 | F8: 46049 | G8: MGR-02 | H8: =IF(F8="","Active","Terminated") -> Terminated
A9: E008 | B9: Diego Ferreira | C9: Treasury | D9: Clerk | E9: 44253 | G9: MGR-01 | H9: =IF(F9="","Active","Terminated") -> Active
A10: E009 | B10: Omar Diallo | C10: IT Operations | D10: Specialist | E10: 43792 | G10: MGR-02 | H10: =IF(F10="","Active","Terminated") -> Active
A11: E010 | B11: Ingrid Khan | C11: Treasury | D11: Clerk | E11: 44132 | G11: MGR-04 | H11: =IF(F11="","Active","Terminated") -> Active
A12: E011 | B12: Ingrid Reyes | C12: Accounts Payable | D12: Senior Analyst | E12: 44166 | G12: MGR-04 | H12: =IF(F12="","Active","Terminated") -> Active
A13: E012 | B13: Zara Santos | C13: IT Operations | D13: Analyst | E13: 45747 | G13: MGR-06 | H13: =IF(F13="","Active","Terminated") -> Active
A14: E013 | B14: Omar Ferreira | C14: Finance | D14: Senior Analyst | E14: 44758 | G14: MGR-02 | H14: =IF(F14="","Active","Terminated") -> Active
A15: E014 | B15: Raj Osei | C15: Treasury | D15: Clerk | E15: 44336 | G15: MGR-07 | H15: =IF(F15="","Active","Terminated") -> Active
A16: E015 | B16: Zara Silva | C16: IT Operations | D16: Manager | E16: 44037 | G16: MGR-09 | H16: =IF(F16="","Active","Terminated") -> Active
A17: E016 | B17: Tariq Petrov | C17: HR | D17: Manager | E17: 45101 | G17: MGR-03 | H17: =IF(F17="","Active","Terminated") -> Active
A18: E017 | B18: Isabel Okafor | C18: Finance | D18: Manager | E18: 43915 | F18: 45821 | G18: MGR-07 | H18: =IF(F18="","Active","Terminated") -> Terminated
A19: E018 | B19: Carlos Santos | C19: HR | D19: Analyst | E19: 45383 | G19: MGR-09 | H19: =IF(F19="","Active","Terminated") -> Active
A20: E019 | B20: Sophia Abara | C20: Procurement | D20: Analyst | E20: 44558 | G20: MGR-06 | H20: =IF(F20="","Active","Terminated") -> Active
A21: E020 | B21: Diego Ivanov | C21: Payroll | D21: Senior Analyst | E21: 45324 | F21: 45927 | G21: MGR-09 | H21: =IF(F21="","Active","Terminated") -> Terminated
A22: E021 | B22: Kofi Braga | C22: Accounts Payable | D22: Manager | E22: 44688 | G22: MGR-09 | H22: =IF(F22="","Active","Terminated") -> Active
A23: E022 | B23: Rahul Silva | C23: Treasury | D23: Analyst | E23: 44127 | G23: MGR-09 | H23: =IF(F23="","Active","Terminated") -> Active
A24: E023 | B24: Youssef Andersson | C24: Customer Service | D24: Senior Analyst | E24: 43545 | F24: 46029 | G24: MGR-05 | H24: =IF(F24="","Active","Terminated") -> Terminated
A25: E024 | B25: Priya Rossi | C25: Accounts Payable | D25: Manager | E25: 43816 | G25: MGR-02 | H25: =IF(F25="","Active","Terminated") -> Active
A26: E025 | B26: Kenji Silva | C26: Customer Service | D26: Specialist | E26: 45717 | F26: 46257 | G26: MGR-10 | H26: =IF(F26="","Active","Terminated") -> Terminated
A27: E026 | B27: Grace Braga | C27: Procurement | D27: Clerk | E27: 44289 | G27: MGR-07 | H27: =IF(F27="","Active","Terminated") -> Active
A28: E027 | B28: Laura Khan | C28: Procurement | D28: Associate | E28: 45315 | F28: 45888 | G28: MGR-02 | H28: =IF(F28="","Active","Terminated") -> Terminated
A29: E028 | B29: Maria Haruki | C29: Procurement | D29: Analyst | E29: 44408 | G29: MGR-01 | H29: =IF(F29="","Active","Terminated") -> Active
A30: E029 | B30: Carlos Osei | C30: Finance | D30: Clerk | E30: 44819 | F30: 45901 | G30: MGR-05 | H30: =IF(F30="","Active","Terminated") -> Terminated
A31: E030 | B31: Isabel Nakamura | C31: Procurement | D31: Manager | E31: 44007 | G31: MGR-10 | H31: =IF(F31="","Active","Terminated") -> Active
A32: E031 | B32: Adam Rossi | C32: Customer Service | D32: Clerk | E32: 45133 | G32: MGR-02 | H32: =IF(F32="","Active","Terminated") -> Active
A33: E032 | B33: Olivia Kim | C33: HR | D33: Clerk | E33: 45149 | G33: MGR-01 | H33: =IF(F33="","Active","Terminated") -> Active
A34: E033 | B34: Liam Garcia | C34: HR | D34: Senior Analyst | E34: 44855 | G34: MGR-02 | H34: =IF(F34="","Active","Terminated") -> Active
A35: E034 | B35: Rahul Nakamura | C35: Procurement | D35: Specialist | E35: 45303 | F35: 45845 | G35: MGR-05 | H35: =IF(F35="","Active","Terminated") -> Terminated
A36: E035 | B36: Chloe Kowalski | C36: Accounts Payable | D36: Analyst | E36: 45281 | G36: MGR-09 | H36: =IF(F36="","Active","Terminated") -> Active
A37: E036 | B37: Priya Schmidt | C37: Procurement | D37: Senior Analyst | E37: 43526 | G37: MGR-04 | H37: =IF(F37="","Active","Terminated") -> Active
A38: E037 | B38: Sanjay Dubois | C38: Customer Service | D38: Senior Analyst | E38: 44341 | G38: MGR-01 | H38: =IF(F38="","Active","Terminated") -> Active
A39: E038 | B39: Victor Chen | C39: HR | D39: Associate | E39: 44552 | G39: MGR-08 | H39: =IF(F39="","Active","Terminated") -> Active
A40: E039 | B40: Olivia Reyes | C40: Procurement | D40: Analyst | E40: 45459 | F40: 45961 | G40: MGR-04 | H40: =IF(F40="","Active","Terminated") -> Terminated
...

Sheet SoD_Conflict_Matrix
A1: RuleID | B1: RoleA_ID | C1: RoleA_Name | D1: RoleB_ID | E1: RoleB_Name | F1: ConflictRationale
A2: SOD-01 | B2: R01 | C2: AP Invoice Entry | D2: R02 | E2: AP Payment Approval | F2: Same user can enter AND approve AP invoices/payments (fictitious vendor payment risk)
A3: SOD-02 | B3: R03 | C3: Vendor Master Maintenance | D3: R02 | E3: AP Payment Approval | F3: Same user can create/edit vendor master AND approve payments (ghost vendor fraud risk)
A4: SOD-03 | B4: R04 | C4: GL Journal Posting | D4: R05 | E4: GL Journal Approval | F4: Same user can post AND approve GL journal entries (unauthorized/erroneous entries risk)
A5: SOD-04 | B5: R06 | C5: Payroll Data Entry | D5: R07 | E5: Payroll Approval / Release | F5: Same user can enter AND approve/release payroll (ghost employee / inflated pay risk)
A6: SOD-05 | B6: R11 | C6: Sales Order Entry | D6: R12 | E6: Sales Credit Memo Approval | F6: Same user can enter sales orders AND approve credit memos (revenue manipulation risk)
A7: SOD-06 | B7: R13 | C7: Wire Initiation | D7: R14 | E7: Wire Approval / Release | F7: Same user can initiate AND approve/release wire transfers (unauthorized funds transfer risk)

Sheet Access_Grants
A1: GrantID | B1: EmployeeID | C1: EmployeeName | D1: Department | E1: SystemID | F1: RoleID | G1: RoleName | H1: AccessLevel | I1: GrantDate | J1: ApprovedBy | K1: ApprovalDocRef | L1: Status | M1: RevokeDate
A2: AG-0001 | B2: E001 | C2: Sophia Chen | D2: IT Operations | E2: SYS-AD | F2: R09 | G2: Standard Network User | H2: Read | I2: 45031 | J2: MGR-02 | K2: CHG-93136 | L2: Active
A3: AG-0002 | B3: E001 | C3: Sophia Chen | D3: IT Operations | E3: SYS-HRIS | F3: R08 | G3: Employee Master Read-Only | H3: Read | I3: 44934 | J3: MGR-06 | K3: CHG-27146 | L3: Active
A4: AG-0003 | B4: E001 | C4: Sophia Chen | D4: IT Operations | E4: SYS-AD | F4: R10 | G4: Domain Administrator | H4: Admin | I4: 45831 | J4: MGR-09 | K4: CHG-66057 | L4: Active
A5: AG-0004 | B5: E002 | C5: Peter Okafor | D5: HR | E5: SYS-AD | F5: R09 | G5: Standard Network User | H5: Read | I5: 44964 | K5: CHG-26704 | L5: Revoked | M5: 45882
A6: AG-0005 | B6: E002 | C6: Peter Okafor | D6: HR | E6: SYS-HRIS | F6: R07 | G6: Payroll Approval / Release | H6: Admin | I6: 45018 | J6: MGR-04 | K6: CHG-99399 | L6: Active
A7: AG-0006 | B7: E002 | C7: Peter Okafor | D7: HR | E7: SYS-HRIS | F7: R06 | G7: Payroll Data Entry | H7: Write | I7: 45070 | J7: MGR-07 | K7: CHG-91351 | L7: Revoked | M7: 45883
A8: AG-0007 | B8: E002 | C8: Peter Okafor | D8: HR | E8: SYS-HRIS | F8: R08 | G8: Employee Master Read-Only | H8: Read | I8: 44968 | J8: MGR-03 | L8: Active
A9: AG-0008 | B9: E003 | C9: Youssef Chen | D9: Procurement | E9: SYS-AD | F9: R09 | G9: Standard Network User | H9: Read | I9: 45037 | J9: MGR-07 | K9: CHG-15075 | L9: Active
A10: AG-0009 | B10: E003 | C10: Youssef Chen | D10: Procurement | E10: SYS-ERP | F10: R03 | G10: Vendor Master Maintenance | H10: Write | I10: 45763 | J10: MGR-08 | K10: CHG-55830 | L10: Active
A11: AG-0010 | B11: E003 | C11: Youssef Chen | D11: Procurement | E11: SYS-ERP | F11: R01 | G11: AP Invoice Entry | H11: Write | I11: 45160 | J11: MGR-04 | K11: CHG-13101 | L11: Active
A12: AG-0011 | B12: E004 | C12: Omar Khan | D12: IT Operations | E12: SYS-AD | F12: R10 | G12: Domain Administrator | H12: Admin | I12: 44978 | J12: System Auto-Provision | K12: CHG-80282 | L12: Revoked | M12: 45512
A13: AG-0012 | B13: E004 | C13: Omar Khan | D13: IT Operations | E13: SYS-HRIS | F13: R08 | G13: Employee Master Read-Only | H13: Read | I13: 44949 | J13: MGR-10 | L13: Active
A14: AG-0013 | B14: E004 | C14: Omar Khan | D14: IT Operations | E14: SYS-AD | F14: R09 | G14: Standard Network User | H14: Read | I14: 44967 | J14: MGR-07 | K14: CHG-89457 | L14: Active
A15: AG-0014 | B15: E005 | C15: Olivia Andersson | D15: IT Operations | E15: SYS-AD | F15: R10 | G15: Domain Administrator | H15: Admin | I15: 44928 | J15: MGR-09 | K15: CHG-80575 | L15: Active
A16: AG-0015 | B16: E005 | C16: Olivia Andersson | D16: IT Operations | E16: SYS-HRIS | F16: R08 | G16: Employee Master Read-Only | H16: Read | I16: 45128 | J16: MGR-06 | L16: Active
A17: AG-0016 | B17: E005 | C17: Olivia Andersson | D17: IT Operations | E17: SYS-AD | F17: R09 | G17: Standard Network User | H17: Read | I17: 45248 | J17: System Auto-Provision | K17: CHG-26334 | L17: Active
A18: AG-0017 | B18: E006 | C18: Fatima Santos | D18: Accounts Payable | E18: SYS-ERP | F18: R03 | G18: Vendor Master Maintenance | H18: Write | I18: 46071 | J18: MGR-03 | K18: CHG-35144 | L18: Active
A19: AG-0018 | B19: E006 | C19: Fatima Santos | D19: Accounts Payable | E19: SYS-HRIS | F19: R08 | G19: Employee Master Read-Only | H19: Read | I19: 45292 | J19: MGR-10 | K19: CHG-84593 | L19: Active
A20: AG-0019 | B20: E006 | C20: Fatima Santos | D20: Accounts Payable | E20: SYS-AD | F20: R09 | G20: Standard Network User | H20: Read | I20: 44936 | J20: MGR-05 | K20: CHG-47606 | L20: Active
A21: AG-0020 | B21: E007 | C21: Wei Petrov | D21: Customer Service | E21: SYS-HRIS | F21: R08 | G21: Employee Master Read-Only | H21: Read | I21: 45880 | J21: MGR-09 | K21: CHG-72021 | L21: Revoked | M21: 46054
A22: AG-0021 | B22: E007 | C22: Wei Petrov | D22: Customer Service | E22: SYS-CRM | F22: R11 | G22: Sales Order Entry | H22: Write | I22: 45835 | J22: System Auto-Provision | K22: CHG-21114 | L22: Revoked | M22: 46053
A23: AG-0022 | B23: E007 | C23: Wei Petrov | D23: Customer Service | E23: SYS-AD | F23: R09 | G23: Standard Network User | H23: Read | I23: 46005 | J23: MGR-02 | K23: CHG-40784 | L23: Active
A24: AG-0023 | B24: E008 | C24: Diego Ferreira | D24: Treasury | E24: SYS-BANK | F24: R14 | G24: Wire Approval / Release | H24: Admin | I24: 45552 | J24: MGR-02 | K24: CHG-69692 | L24: Active
A25: AG-0024 | B25: E008 | C25: Diego Ferreira | D25: Treasury | E25: SYS-AD | F25: R09 | G25: Standard Network User | H25: Read | I25: 45126 | J25: MGR-07 | K25: CHG-74799 | L25: Active
A26: AG-0025 | B26: E008 | C26: Diego Ferreira | D26: Treasury | E26: SYS-HRIS | F26: R06 | G26: Payroll Data Entry | H26: Write | I26: 45631 | J26: MGR-01 | K26: CHG-23970 | L26: Active
A27: AG-0026 | B27: E008 | C27: Diego Ferreira | D27: Treasury | E27: SYS-HRIS | F27: R07 | G27: Payroll Approval / Release | H27: Admin | I27: 45750 | K27: CHG-70889 | L27: Active
A28: AG-0027 | B28: E009 | C28: Omar Diallo | D28: IT Operations | E28: SYS-AD | F28: R10 | G28: Domain Administrator | H28: Admin | I28: 45153 | J28: MGR-10 | K28: CHG-76162 | L28: Active
A29: AG-0028 | B29: E009 | C29: Omar Diallo | D29: IT Operations | E29: SYS-HRIS | F29: R08 | G29: Employee Master Read-Only | H29: Read | I29: 45155 | J29: MGR-03 | K29: CHG-72216 | L29: Active
A30: AG-0029 | B30: E009 | C30: Omar Diallo | D30: IT Operations | E30: SYS-AD | F30: R09 | G30: Standard Network User | H30: Read | I30: 45253 | J30: MGR-05 | K30: CHG-78327 | L30: Active
A31: AG-0030 | B31: E010 | C31: Ingrid Khan | D31: Treasury | E31: SYS-AD | F31: R09 | G31: Standard Network User | H31: Read | I31: 45270 | K31: CHG-80798 | L31: Active
A32: AG-0031 | B32: E010 | C32: Ingrid Khan | D32: Treasury | E32: SYS-BANK | F32: R13 | G32: Wire Initiation | H32: Write | I32: 45083 | J32: MGR-04 | K32: CHG-18418 | L32: Active
A33: AG-0032 | B33: E010 | C33: Ingrid Khan | D33: Treasury | E33: SYS-BANK | F33: R14 | G33: Wire Approval / Release | H33: Admin | I33: 45404 | J33: MGR-07 | K33: CHG-18161 | L33: Active
A34: AG-0033 | B34: E011 | C34: Ingrid Reyes | D34: Accounts Payable | E34: SYS-ERP | F34: R01 | G34: AP Invoice Entry | H34: Write | I34: 45232 | J34: MGR-07 | K34: CHG-64921 | L34: Active
A35: AG-0034 | B35: E011 | C35: Ingrid Reyes | D35: Accounts Payable | E35: SYS-ERP | F35: R03 | G35: Vendor Master Maintenance | H35: Write | I35: 45544 | J35: MGR-04 | K35: CHG-73993 | L35: Active
A36: AG-0035 | B36: E011 | C36: Ingrid Reyes | D36: Accounts Payable | E36: SYS-AD | F36: R09 | G36: Standard Network User | H36: Read | I36: 44956 | J36: MGR-07 | K36: CHG-54057 | L36: Active
A37: AG-0036 | B37: E011 | C37: Ingrid Reyes | D37: Accounts Payable | E37: SYS-ERP | F37: R02 | G37: AP Payment Approval | H37: Write | I37: 45096 | J37: MGR-08 | K37: CHG-26728 | L37: Active
A38: AG-0037 | B38: E012 | C38: Zara Santos | D38: IT Operations | E38: SYS-AD | F38: R09 | G38: Standard Network User | H38: Read | I38: 45885 | K38: CHG-33819 | L38: Active
A39: AG-0038 | B39: E012 | C39: Zara Santos | D39: IT Operations | E39: SYS-AD | F39: R10 | G39: Domain Administrator | H39: Admin | I39: 46081 | J39: MGR-06 | K39: CHG-59692 | L39: Active
A40: AG-0039 | B40: E012 | C40: Zara Santos | D40: IT Operations | E40: SYS-HRIS | F40: R08 | G40: Employee Master Read-Only | H40: Read | I40: 46178 | J40: MGR-05 | K40: CHG-20735 | L40: Active
...

Sheet Recertifications
A1: RecertID | B1: EmployeeID | C1: EmployeeName | D1: SystemID | E1: RoleID | F1: RoleName | G1: AccessLevel | H1: ReviewCycleDays | I1: DueDate | J1: Reviewer | K1: CompletedDate | L1: Result | M1: Recert_Status
A2: RC-0001 | B2: E001 | C2: Sophia Chen | D2: SYS-AD | E2: R09 | F2: Standard Network User | G2: Read | H2: 365 | I2: 46260 | J2: MGR-02 | K2: 46243 | L2: Access Confirmed Appropriate | M2: =IF(ISBLANK(K2),IF(TODAY()>I2,"OVERDUE - NOT COMPLETED","PENDING - NOT YET DUE"),IF(K2>I2,"COMPLETED LATE","COMPLETED ON TIME")) -> COMPLETED ON TIME
A3: RC-0002 | B3: E001 | C3: Sophia Chen | D3: SYS-HRIS | E3: R08 | F3: Employee Master Read-Only | G3: Read | H3: 365 | I3: 46071 | J3: MGR-06 | M3: =IF(ISBLANK(K3),IF(TODAY()>I3,"OVERDUE - NOT COMPLETED","PENDING - NOT YET DUE"),IF(K3>I3,"COMPLETED LATE","COMPLETED ON TIME")) -> OVERDUE - NOT COMPLETED
A4: RC-0003 | B4: E001 | C4: Sophia Chen | D4: SYS-AD | E4: R10 | F4: Domain Administrator | G4: Admin | H4: 90 | I4: 46272 | J4: MGR-07 | M4: =IF(ISBLANK(K4),IF(TODAY()>I4,"OVERDUE - NOT COMPLETED","PENDING - NOT YET DUE"),IF(K4>I4,"COMPLETED LATE","COMPLETED ON TIME")) -> OVERDUE - NOT COMPLETED
A5: RC-0004 | B5: E002 | C5: Peter Okafor | D5: SYS-HRIS | E5: R07 | F5: Payroll Approval / Release | G5: Admin | H5: 90 | I5: 46272 | J5: MGR-09 | K5: 46262 | L5: Access Confirmed Appropriate | M5: =IF(ISBLANK(K5),IF(TODAY()>I5,"OVERDUE - NOT COMPLETED","PENDING - NOT YET DUE"),IF(K5>I5,"COMPLETED LATE","COMPLETED ON TIME")) -> COMPLETED ON TIME
A6: RC-0005 | B6: E002 | C6: Peter Okafor | D6: SYS-HRIS | E6: R08 | F6: Employee Master Read-Only | G6: Read | H6: 365 | I6: 46457 | J6: MGR-02 | K6: 46444 | L6: Access Revoked - No Longer Needed | M6: =IF(ISBLANK(K6),IF(TODAY()>I6,"OVERDUE - NOT COMPLETED","PENDING - NOT YET DUE"),IF(K6>I6,"COMPLETED LATE","COMPLETED ON TIME")) -> COMPLETED ON TIME
A7: RC-0006 | B7: E003 | C7: Youssef Chen | D7: SYS-AD | E7: R09 | F7: Standard Network User | G7: Read | H7: 365 | I7: 46234 | J7: MGR-03 | K7: 46224 | L7: Access Confirmed Appropriate | M7: =IF(ISBLANK(K7),IF(TODAY()>I7,"OVERDUE - NOT COMPLETED","PENDING - NOT YET DUE"),IF(K7>I7,"COMPLETED LATE","COMPLETED ON TIME")) -> COMPLETED ON TIME
A8: RC-0007 | B8: E003 | C8: Youssef Chen | D8: SYS-ERP | E8: R03 | F8: Vendor Master Maintenance | G8: Write | H8: 365 | I8: 46076 | J8: MGR-02 | K8: 46083 | L8: Access Revoked - No Longer Needed | M8: =IF(ISBLANK(K8),IF(TODAY()>I8,"OVERDUE - NOT COMPLETED","PENDING - NOT YET DUE"),IF(K8>I8,"COMPLETED LATE","COMPLETED ON TIME")) -> COMPLETED LATE
A9: RC-0008 | B9: E003 | C9: Youssef Chen | D9: SYS-ERP | E9: R01 | F9: AP Invoice Entry | G9: Write | H9: 365 | I9: 45956 | J9: MGR-06 | K9: 45937 | L9: Access Confirmed Appropriate | M9: =IF(ISBLANK(K9),IF(TODAY()>I9,"OVERDUE - NOT COMPLETED","PENDING - NOT YET DUE"),IF(K9>I9,"COMPLETED LATE","COMPLETED ON TIME")) -> COMPLETED ON TIME
A10: RC-0009 | B10: E004 | C10: Omar Khan | D10: SYS-HRIS | E10: R08 | F10: Employee Master Read-Only | G10: Read | H10: 365 | I10: 46084 | J10: MGR-03 | K10: 46065 | L10: Access Confirmed Appropriate | M10: =IF(ISBLANK(K10),IF(TODAY()>I10,"OVERDUE - NOT COMPLETED","PENDING - NOT YET DUE"),IF(K10>I10,"COMPLETED LATE","COMPLETED ON TIME")) -> COMPLETED ON TIME
A11: RC-0010 | B11: E004 | C11: Omar Khan | D11: SYS-AD | E11: R09 | F11: Standard Network User | G11: Read | H11: 365 | I11: 46338 | J11: MGR-06 | K11: 46331 | L11: Access Confirmed Appropriate | M11: =IF(ISBLANK(K11),IF(TODAY()>I11,"OVERDUE - NOT COMPLETED","PENDING - NOT YET DUE"),IF(K11>I11,"COMPLETED LATE","COMPLETED ON TIME")) -> COMPLETED ON TIME
A12: RC-0011 | B12: E005 | C12: Olivia Andersson | D12: SYS-AD | E12: R10 | F12: Domain Administrator | G12: Admin | H12: 90 | I12: 46252 | J12: MGR-09 | K12: 46283 | L12: Access Confirmed Appropriate | M12: =IF(ISBLANK(K12),IF(TODAY()>I12,"OVERDUE - NOT COMPLETED","PENDING - NOT YET DUE"),IF(K12>I12,"COMPLETED LATE","COMPLETED ON TIME")) -> COMPLETED LATE
A13: RC-0012 | B13: E005 | C13: Olivia Andersson | D13: SYS-HRIS | E13: R08 | F13: Employee Master Read-Only | G13: Read | H13: 365 | I13: 46369 | J13: MGR-08 | K13: 46357 | L13: Access Revoked - No Longer Needed | M13: =IF(ISBLANK(K13),IF(TODAY()>I13,"OVERDUE - NOT COMPLETED","PENDING - NOT YET DUE"),IF(K13>I13,"COMPLETED LATE","COMPLETED ON TIME")) -> COMPLETED ON TIME
A14: RC-0013 | B14: E005 | C14: Olivia Andersson | D14: SYS-AD | E14: R09 | F14: Standard Network User | G14: Read | H14: 365 | I14: 46122 | J14: MGR-10 | M14: =IF(ISBLANK(K14),IF(TODAY()>I14,"OVERDUE - NOT COMPLETED","PENDING - NOT YET DUE"),IF(K14>I14,"COMPLETED LATE","COMPLETED ON TIME")) -> OVERDUE - NOT COMPLETED
A15: RC-0014 | B15: E006 | C15: Fatima Santos | D15: SYS-ERP | E15: R03 | F15: Vendor Master Maintenance | G15: Write | H15: 365 | I15: 46410 | J15: MGR-06 | K15: 46407 | L15: Access Revoked - No Longer Needed | M15: =IF(ISBLANK(K15),IF(TODAY()>I15,"OVERDUE - NOT COMPLETED","PENDING - NOT YET DUE"),IF(K15>I15,"COMPLETED LATE","COMPLETED ON TIME")) -> COMPLETED ON TIME
A16: RC-0015 | B16: E006 | C16: Fatima Santos | D16: SYS-AD | E16: R09 | F16: Standard Network User | G16: Read | H16: 365 | I16: 46197 | J16: MGR-08 | K16: 46193 | L16: Access Confirmed Appropriate | M16: =IF(ISBLANK(K16),IF(TODAY()>I16,"OVERDUE - NOT COMPLETED","PENDING - NOT YET DUE"),IF(K16>I16,"COMPLETED LATE","COMPLETED ON TIME")) -> COMPLETED ON TIME
A17: RC-0016 | B17: E007 | C17: Wei Petrov | D17: SYS-AD | E17: R09 | F17: Standard Network User | G17: Read | H17: 365 | I17: 46379 | J17: MGR-06 | K17: 46366 | L17: Access Confirmed Appropriate | M17: =IF(ISBLANK(K17),IF(TODAY()>I17,"OVERDUE - NOT COMPLETED","PENDING - NOT YET DUE"),IF(K17>I17,"COMPLETED LATE","COMPLETED ON TIME")) -> COMPLETED ON TIME
A18: RC-0017 | B18: E008 | C18: Diego Ferreira | D18: SYS-BANK | E18: R14 | F18: Wire Approval / Release | G18: Admin | H18: 90 | I18: 46253 | J18: MGR-07 | K18: 46242 | L18: Access Confirmed Appropriate | M18: =IF(ISBLANK(K18),IF(TODAY()>I18,"OVERDUE - NOT COMPLETED","PENDING - NOT YET DUE"),IF(K18>I18,"COMPLETED LATE","COMPLETED ON TIME")) -> COMPLETED ON TIME
A19: RC-0018 | B19: E008 | C19: Diego Ferreira | D19: SYS-AD | E19: R09 | F19: Standard Network User | G19: Read | H19: 365 | I19: 46261 | J19: MGR-03 | M19: =IF(ISBLANK(K19),IF(TODAY()>I19,"OVERDUE - NOT COMPLETED","PENDING - NOT YET DUE"),IF(K19>I19,"COMPLETED LATE","COMPLETED ON TIME")) -> OVERDUE - NOT COMPLETED
A20: RC-0019 | B20: E008 | C20: Diego Ferreira | D20: SYS-HRIS | E20: R06 | F20: Payroll Data Entry | G20: Write | H20: 365 | I20: 46060 | J20: MGR-08 | K20: 46060 | L20: Access Confirmed Appropriate | M20: =IF(ISBLANK(K20),IF(TODAY()>I20,"OVERDUE - NOT COMPLETED","PENDING - NOT YET DUE"),IF(K20>I20,"COMPLETED LATE","COMPLETED ON TIME")) -> COMPLETED ON TIME
A21: RC-0020 | B21: E008 | C21: Diego Ferreira | D21: SYS-HRIS | E21: R07 | F21: Payroll Approval / Release | G21: Admin | H21: 90 | I21: 46231 | J21: MGR-09 | K21: 46212 | L21: Access Revoked - No Longer Needed | M21: =IF(ISBLANK(K21),IF(TODAY()>I21,"OVERDUE - NOT COMPLETED","PENDING - NOT YET DUE"),IF(K21>I21,"COMPLETED LATE","COMPLETED ON TIME")) -> COMPLETED ON TIME
A22: RC-0021 | B22: E009 | C22: Omar Diallo | D22: SYS-AD | E22: R10 | F22: Domain Administrator | G22: Admin | H22: 90 | I22: 46253 | J22: MGR-05 | M22: =IF(ISBLANK(K22),IF(TODAY()>I22,"OVERDUE - NOT COMPLETED","PENDING - NOT YET DUE"),IF(K22>I22,"COMPLETED LATE","COMPLETED ON TIME")) -> OVERDUE - NOT COMPLETED
A23: RC-0022 | B23: E009 | C23: Omar Diallo | D23: SYS-HRIS | E23: R08 | F23: Employee Master Read-Only | G23: Read | H23: 365 | I23: 46386 | J23: MGR-02 | M23: =IF(ISBLANK(K23),IF(TODAY()>I23,"OVERDUE - NOT COMPLETED","PENDING - NOT YET DUE"),IF(K23>I23,"COMPLETED LATE","COMPLETED ON TIME")) -> PENDING - NOT YET DUE
A24: RC-0023 | B24: E010 | C24: Ingrid Khan | D24: SYS-AD | E24: R09 | F24: Standard Network User | G24: Read | H24: 365 | I24: 46445 | J24: MGR-10 | M24: =IF(ISBLANK(K24),IF(TODAY()>I24,"OVERDUE - NOT COMPLETED","PENDING - NOT YET DUE"),IF(K24>I24,"COMPLETED LATE","COMPLETED ON TIME")) -> PENDING - NOT YET DUE
A25: RC-0024 | B25: E010 | C25: Ingrid Khan | D25: SYS-BANK | E25: R13 | F25: Wire Initiation | G25: Write | H25: 365 | I25: 46279 | J25: MGR-04 | K25: 46274 | L25: Access Confirmed Appropriate | M25: =IF(ISBLANK(K25),IF(TODAY()>I25,"OVERDUE - NOT COMPLETED","PENDING - NOT YET DUE"),IF(K25>I25,"COMPLETED LATE","COMPLETED ON TIME")) -> COMPLETED ON TIME
A26: RC-0025 | B26: E010 | C26: Ingrid Khan | D26: SYS-BANK | E26: R14 | F26: Wire Approval / Release | G26: Admin | H26: 90 | I26: 46210 | J26: MGR-09 | K26: 46194 | L26: Access Revoked - No Longer Needed | M26: =IF(ISBLANK(K26),IF(TODAY()>I26,"OVERDUE - NOT COMPLETED","PENDING - NOT YET DUE"),IF(K26>I26,"COMPLETED LATE","COMPLETED ON TIME")) -> COMPLETED ON TIME
A27: RC-0026 | B27: E011 | C27: Ingrid Reyes | D27: SYS-ERP | E27: R01 | F27: AP Invoice Entry | G27: Write | H27: 365 | I27: 45962 | J27: MGR-07 | K27: 45954 | L27: Access Confirmed Appropriate | M27: =IF(ISBLANK(K27),IF(TODAY()>I27,"OVERDUE - NOT COMPLETED","PENDING - NOT YET DUE"),IF(K27>I27,"COMPLETED LATE","COMPLETED ON TIME")) -> COMPLETED ON TIME
A28: RC-0027 | B28: E011 | C28: Ingrid Reyes | D28: SYS-ERP | E28: R03 | F28: Vendor Master Maintenance | G28: Write | H28: 365 | I28: 46271 | J28: MGR-04 | K28: 46251 | L28: Access Confirmed Appropriate | M28: =IF(ISBLANK(K28),IF(TODAY()>I28,"OVERDUE - NOT COMPLETED","PENDING - NOT YET DUE"),IF(K28>I28,"COMPLETED LATE","COMPLETED ON TIME")) -> COMPLETED ON TIME
A29: RC-0028 | B29: E011 | C29: Ingrid Reyes | D29: SYS-AD | E29: R09 | F29: Standard Network User | G29: Read | H29: 365 | I29: 46054 | J29: MGR-01 | K29: 46044 | L29: Access Confirmed Appropriate | M29: =IF(ISBLANK(K29),IF(TODAY()>I29,"OVERDUE - NOT COMPLETED","PENDING - NOT YET DUE"),IF(K29>I29,"COMPLETED LATE","COMPLETED ON TIME")) -> COMPLETED ON TIME
A30: RC-0029 | B30: E011 | C30: Ingrid Reyes | D30: SYS-ERP | E30: R02 | F30: AP Payment Approval | G30: Write | H30: 365 | I30: 46393 | J30: MGR-08 | K30: 46389 | L30: Access Confirmed Appropriate | M30: =IF(ISBLANK(K30),IF(TODAY()>I30,"OVERDUE - NOT COMPLETED","PENDING - NOT YET DUE"),IF(K30>I30,"COMPLETED LATE","COMPLETED ON TIME")) -> COMPLETED ON TIME
A31: RC-0030 | B31: E012 | C31: Zara Santos | D31: SYS-AD | E31: R09 | F31: Standard Network User | G31: Read | H31: 365 | I31: 45955 | J31: MGR-05 | K31: 45968 | L31: Access Confirmed Appropriate | M31: =IF(ISBLANK(K31),IF(TODAY()>I31,"OVERDUE - NOT COMPLETED","PENDING - NOT YET DUE"),IF(K31>I31,"COMPLETED LATE","COMPLETED ON TIME")) -> COMPLETED LATE
A32: RC-0031 | B32: E012 | C32: Zara Santos | D32: SYS-AD | E32: R10 | F32: Domain Administrator | G32: Admin | H32: 90 | I32: 46324 | J32: MGR-07 | K32: 46307 | L32: Access Confirmed Appropriate | M32: =IF(ISBLANK(K32),IF(TODAY()>I32,"OVERDUE - NOT COMPLETED","PENDING - NOT YET DUE"),IF(K32>I32,"COMPLETED LATE","COMPLETED ON TIME")) -> COMPLETED ON TIME
A33: RC-0032 | B33: E012 | C33: Zara Santos | D33: SYS-HRIS | E33: R08 | F33: Employee Master Read-Only | G33: Read | H33: 365 | I33: 46113 | J33: MGR-05 | K33: 46206 | L33: Access Confirmed Appropriate | M33: =IF(ISBLANK(K33),IF(TODAY()>I33,"OVERDUE - NOT COMPLETED","PENDING - NOT YET DUE"),IF(K33>I33,"COMPLETED LATE","COMPLETED ON TIME")) -> COMPLETED LATE
A34: RC-0033 | B34: E013 | C34: Omar Ferreira | D34: SYS-ERP | E34: R05 | F34: GL Journal Approval | G34: Admin | H34: 90 | I34: 46304 | J34: MGR-07 | K34: 46292 | L34: Access Confirmed Appropriate | M34: =IF(ISBLANK(K34),IF(TODAY()>I34,"OVERDUE - NOT COMPLETED","PENDING - NOT YET DUE"),IF(K34>I34,"COMPLETED LATE","COMPLETED ON TIME")) -> COMPLETED ON TIME
A35: RC-0034 | B35: E014 | C35: Raj Osei | D35: SYS-BANK | E35: R13 | F35: Wire Initiation | G35: Write | H35: 365 | I35: 46294 | J35: MGR-09 | M35: =IF(ISBLANK(K35),IF(TODAY()>I35,"OVERDUE - NOT COMPLETED","PENDING - NOT YET DUE"),IF(K35>I35,"COMPLETED LATE","COMPLETED ON TIME")) -> PENDING - NOT YET DUE
A36: RC-0035 | B36: E015 | C36: Zara Silva | D36: SYS-HRIS | E36: R08 | F36: Employee Master Read-Only | G36: Read | H36: 365 | I36: 46358 | J36: MGR-10 | K36: 46353 | L36: Access Revoked - No Longer Needed | M36: =IF(ISBLANK(K36),IF(TODAY()>I36,"OVERDUE - NOT COMPLETED","PENDING - NOT YET DUE"),IF(K36>I36,"COMPLETED LATE","COMPLETED ON TIME")) -> COMPLETED ON TIME
A37: RC-0036 | B37: E015 | C37: Zara Silva | D37: SYS-AD | E37: R09 | F37: Standard Network User | G37: Read | H37: 365 | I37: 45999 | J37: MGR-06 | K37: 45990 | L37: Access Confirmed Appropriate | M37: =IF(ISBLANK(K37),IF(TODAY()>I37,"OVERDUE - NOT COMPLETED","PENDING - NOT YET DUE"),IF(K37>I37,"COMPLETED LATE","COMPLETED ON TIME")) -> COMPLETED ON TIME
A38: RC-0037 | B38: E015 | C38: Zara Silva | D38: SYS-BANK | E38: R13 | F38: Wire Initiation | G38: Write | H38: 365 | I38: 46088 | J38: MGR-08 | K38: 46087 | L38: Access Confirmed Appropriate | M38: =IF(ISBLANK(K38),IF(TODAY()>I38,"OVERDUE - NOT COMPLETED","PENDING - NOT YET DUE"),IF(K38>I38,"COMPLETED LATE","COMPLETED ON TIME")) -> COMPLETED ON TIME
A39: RC-0038 | B39: E015 | C39: Zara Silva | D39: SYS-BANK | E39: R14 | F39: Wire Approval / Release | G39: Admin | H39: 90 | I39: 46263 | J39: MGR-01 | M39: =IF(ISBLANK(K39),IF(TODAY()>I39,"OVERDUE - NOT COMPLETED","PENDING - NOT YET DUE"),IF(K39>I39,"COMPLETED LATE","COMPLETED ON TIME")) -> OVERDUE - NOT COMPLETED
A40: RC-0039 | B40: E016 | C40: Tariq Petrov | D40: SYS-HRIS | E40: R07 | F40: Payroll Approval / Release | G40: Admin | H40: 90 | I40: 46324 | J40: MGR-03 | K40: 46320 | L40: Escalated for Review | M40: =IF(ISBLANK(K40),IF(TODAY()>I40,"OVERDUE - NOT COMPLETED","PENDING - NOT YET DUE"),IF(K40>I40,"COMPLETED LATE","COMPLETED ON TIME")) -> COMPLETED ON TIME
...

Sheet Audit_Testing
A1: GrantID | B1: EmployeeID | C1: EmployeeName | D1: Department | E1: SystemID | F1: RoleID | G1: RoleName | H1: AccessLevel | I1: GrantStatus | J1: GrantDate | K1: TerminationDate | L1: RevokeDate | M1: Test1_Deprovisioning_Flag | N1: ApprovedBy | O1: ApprovalDocRef | P1: Test2_Approval_Flag | Q1: SoD_ConflictRoleID | R1: SoD_ConflictRoleName | S1: Test3_SoD_Flag | T1: Test4_PrivilegedRecert_Flag | U1: Overall_Exception | V1: Exception_RootCause_Category
A2: =Access_Grants!A2 -> AG-0001 | B2: =Access_Grants!B2 -> E001 | C2: =Access_Grants!C2 -> Sophia Chen | D2: =Access_Grants!D2 -> IT Operations | E2: =Access_Grants!E2 -> SYS-AD | F2: =Access_Grants!F2 -> R09 | G2: =Access_Grants!G2 -> Standard Network User | H2: =Access_Grants!H2 -> Read | I2: =Access_Grants!L2 -> Active | J2: =Access_Grants!I2 -> 45031 | K2: =IFERROR(INDEX(HR_Employees!$F$2:$F$51,MATCH(B2,HR_Employees!$A$2:$A$51,0)),"") -> 0 | L2: =IF(Access_Grants!M2="","",Access_Grants!M2) | M2: =IF(K2="","N/A - Active Employee",IF(OR(I2="Active",AND(L2<>"",L2>K2+5)),"EXCEPTION: TERMINATED USER - ACCESS NOT REVOKED TIMELY","OK - Revoked Within SLA")) -> N/A - Active Employee | N2: =Access_Grants!J2&"" -> MGR-02 | O2: =Access_Grants!K2&"" -> CHG-93136 | P2: =IF(OR(TRIM(N2)="",TRIM(O2)=""),"EXCEPTION: NO DOCUMENTED APPROVAL","OK - Approved") -> OK - Approved | Q2: =IFERROR(INDEX(SoD_Conflict_Matrix!$D$2:$D$7,MATCH(F2,SoD_Conflict_Matrix!$B$2:$B$7,0)),IFERROR(INDEX(SoD_Conflict_Matrix!$B$2:$B$7,MATCH(F2,SoD_Conflict_Matrix!$D$2:$D$7,0)),"")) | R2: =IFERROR(INDEX(SoD_Conflict_Matrix!$E$2:$E$7,MATCH(F2,SoD_Conflict_Matrix!$B$2:$B$7,0)),IFERROR(INDEX(SoD_Conflict_Matrix!$C$2:$C$7,MATCH(F2,SoD_Conflict_Matrix!$D$2:$D$7,0)),"")) | S2: =IF(Q2="","No Conflict Rule Applies to This Role",IF(COUNTIFS(Access_Grants!$B$2:$B$175,B2,Access_Grants!$F$2:$F$175,Q2,Access_Grants!$L$2:$L$175,"Active")>0,"EXCEPTION: SoD CONFLICT - ALSO HOLDS "&R2,"OK - No Conflicting Role Held")) -> No Conflict Rule Applies to This Role | T2: =IF(AND(H2="Admin",I2="Active"),IF(COUNTIFS(Recertifications!$B$2:$B$119,B2,Recertifications!$E$2:$E$119,F2,Recertifications!$K$2:$K$119,"<>")>0,"OK - Recertified","EXCEPTION: PRIVILEGED ACCESS NEVER RECERTIFIED"),"N/A - Not Privileged") -> N/A - Not Privileged | U2: =IF(OR(LEFT(M2,9)="EXCEPTION",LEFT(P2,9)="EXCEPTION",LEFT(S2,9)="EXCEPTION",LEFT(T2,9)="EXCEPTION"),"EXCEPTION","Clean") -> Clean | V2: =IF(LEFT(M2,9)="EXCEPTION","Deprovisioning Control Gap",IF(LEFT(S2,9)="EXCEPTION","Segregation of Duties Conflict",IF(LEFT(P2,9)="EXCEPTION","Provisioning Approval Gap",IF(LEFT(T2,9)="EXCEPTION","Recertification Gap","N/A")))) -> N/A
A3: =Access_Grants!A3 -> AG-0002 | B3: =Access_Grants!B3 -> E001 | C3: =Access_Grants!C3 -> Sophia Chen | D3: =Access_Grants!D3 -> IT Operations | E3: =Access_Grants!E3 -> SYS-HRIS | F3: =Access_Grants!F3 -> R08 | G3: =Access_Grants!G3 -> Employee Master Read-Only | H3: =Access_Grants!H3 -> Read | I3: =Access_Grants!L3 -> Active | J3: =Access_Grants!I3 -> 44934 | K3: =IFERROR(INDEX(HR_Employees!$F$2:$F$51,MATCH(B3,HR_Employees!$A$2:$A$51,0)),"") -> 0 | L3: =IF(Access_Grants!M3="","",Access_Grants!M3) | M3: =IF(K3="","N/A - Active Employee",IF(OR(I3="Active",AND(L3<>"",L3>K3+5)),"EXCEPTION: TERMINATED USER - ACCESS NOT REVOKED TIMELY","OK - Revoked Within SLA")) -> N/A - Active Employee | N3: =Access_Grants!J3&"" -> MGR-06 | O3: =Access_Grants!K3&"" -> CHG-27146 | P3: =IF(OR(TRIM(N3)="",TRIM(O3)=""),"EXCEPTION: NO DOCUMENTED APPROVAL","OK - Approved") -> OK - Approved | Q3: =IFERROR(INDEX(SoD_Conflict_Matrix!$D$2:$D$7,MATCH(F3,SoD_Conflict_Matrix!$B$2:$B$7,0)),IFERROR(INDEX(SoD_Conflict_Matrix!$B$2:$B$7,MATCH(F3,SoD_Conflict_Matrix!$D$2:$D$7,0)),"")) | R3: =IFERROR(INDEX(SoD_Conflict_Matrix!$E$2:$E$7,MATCH(F3,SoD_Conflict_Matrix!$B$2:$B$7,0)),IFERROR(INDEX(SoD_Conflict_Matrix!$C$2:$C$7,MATCH(F3,SoD_Conflict_Matrix!$D$2:$D$7,0)),"")) | S3: =IF(Q3="","No Conflict Rule Applies to This Role",IF(COUNTIFS(Access_Grants!$B$2:$B$175,B3,Access_Grants!$F$2:$F$175,Q3,Access_Grants!$L$2:$L$175,"Active")>0,"EXCEPTION: SoD CONFLICT - ALSO HOLDS "&R3,"OK - No Conflicting Role Held")) -> No Conflict Rule Applies to This Role | T3: =IF(AND(H3="Admin",I3="Active"),IF(COUNTIFS(Recertifications!$B$2:$B$119,B3,Recertifications!$E$2:$E$119,F3,Recertifications!$K$2:$K$119,"<>")>0,"OK - Recertified","EXCEPTION: PRIVILEGED ACCESS NEVER RECERTIFIED"),"N/A - Not Privileged") -> N/A - Not Privileged | U3: =IF(OR(LEFT(M3,9)="EXCEPTION",LEFT(P3,9)="EXCEPTION",LEFT(S3,9)="EXCEPTION",LEFT(T3,9)="EXCEPTION"),"EXCEPTION","Clean") -> Clean | V3: =IF(LEFT(M3,9)="EXCEPTION","Deprovisioning Control Gap",IF(LEFT(S3,9)="EXCEPTION","Segregation of Duties Conflict",IF(LEFT(P3,9)="EXCEPTION","Provisioning Approval Gap",IF(LEFT(T3,9)="EXCEPTION","Recertification Gap","N/A")))) -> N/A
A4: =Access_Grants!A4 -> AG-0003 | B4: =Access_Grants!B4 -> E001 | C4: =Access_Grants!C4 -> Sophia Chen | D4: =Access_Grants!D4 -> IT Operations | E4: =Access_Grants!E4 -> SYS-AD | F4: =Access_Grants!F4 -> R10 | G4: =Access_Grants!G4 -> Domain Administrator | H4: =Access_Grants!H4 -> Admin | I4: =Access_Grants!L4 -> Active | J4: =Access_Grants!I4 -> 45831 | K4: =IFERROR(INDEX(HR_Employees!$F$2:$F$51,MATCH(B4,HR_Employees!$A$2:$A$51,0)),"") -> 0 | L4: =IF(Access_Grants!M4="","",Access_Grants!M4) | M4: =IF(K4="","N/A - Active Employee",IF(OR(I4="Active",AND(L4<>"",L4>K4+5)),"EXCEPTION: TERMINATED USER - ACCESS NOT REVOKED TIMELY","OK - Revoked Within SLA")) -> N/A - Active Employee | N4: =Access_Grants!J4&"" -> MGR-09 | O4: =Access_Grants!K4&"" -> CHG-66057 | P4: =IF(OR(TRIM(N4)="",TRIM(O4)=""),"EXCEPTION: NO DOCUMENTED APPROVAL","OK - Approved") -> OK - Approved | Q4: =IFERROR(INDEX(SoD_Conflict_Matrix!$D$2:$D$7,MATCH(F4,SoD_Conflict_Matrix!$B$2:$B$7,0)),IFERROR(INDEX(SoD_Conflict_Matrix!$B$2:$B$7,MATCH(F4,SoD_Conflict_Matrix!$D$2:$D$7,0)),"")) | R4: =IFERROR(INDEX(SoD_Conflict_Matrix!$E$2:$E$7,MATCH(F4,SoD_Conflict_Matrix!$B$2:$B$7,0)),IFERROR(INDEX(SoD_Conflict_Matrix!$C$2:$C$7,MATCH(F4,SoD_Conflict_Matrix!$D$2:$D$7,0)),"")) | S4: =IF(Q4="","No Conflict Rule Applies to This Role",IF(COUNTIFS(Access_Grants!$B$2:$B$175,B4,Access_Grants!$F$2:$F$175,Q4,Access_Grants!$L$2:$L$175,"Active")>0,"EXCEPTION: SoD CONFLICT - ALSO HOLDS "&R4,"OK - No Conflicting Role Held")) -> No Conflict Rule Applies to This Role | T4: =IF(AND(H4="Admin",I4="Active"),IF(COUNTIFS(Recertifications!$B$2:$B$119,B4,Recertifications!$E$2:$E$119,F4,Recertifications!$K$2:$K$119,"<>")>0,"OK - Recertified","EXCEPTION: PRIVILEGED ACCESS NEVER RECERTIFIED"),"N/A - Not Privileged") -> EXCEPTION: PRIVILEGED ACCESS NEVER RECERTIFIED | U4: =IF(OR(LEFT(M4,9)="EXCEPTION",LEFT(P4,9)="EXCEPTION",LEFT(S4,9)="EXCEPTION",LEFT(T4,9)="EXCEPTION"),"EXCEPTION","Clean") -> EXCEPTION | V4: =IF(LEFT(M4,9)="EXCEPTION","Deprovisioning Control Gap",IF(LEFT(S4,9)="EXCEPTION","Segregation of Duties Conflict",IF(LEFT(P4,9)="EXCEPTION","Provisioning Approval Gap",IF(LEFT(T4,9)="EXCEPTION","Recertification Gap","N/A")))) -> Recertification Gap
A5: =Access_Grants!A5 -> AG-0004 | B5: =Access_Grants!B5 -> E002 | C5: =Access_Grants!C5 -> Peter Okafor | D5: =Access_Grants!D5 -> HR | E5: =Access_Grants!E5 -> SYS-AD | F5: =Access_Grants!F5 -> R09 | G5: =Access_Grants!G5 -> Standard Network User | H5: =Access_Grants!H5 -> Read | I5: =Access_Grants!L5 -> Revoked | J5: =Access_Grants!I5 -> 44964 | K5: =IFERROR(INDEX(HR_Employees!$F$2:$F$51,MATCH(B5,HR_Employees!$A$2:$A$51,0)),"") -> 45881 | L5: =IF(Access_Grants!M5="","",Access_Grants!M5) -> 45882 | M5: =IF(K5="","N/A - Active Employee",IF(OR(I5="Active",AND(L5<>"",L5>K5+5)),"EXCEPTION: TERMINATED USER - ACCESS NOT REVOKED TIMELY","OK - Revoked Within SLA")) -> OK - Revoked Within SLA | N5: =Access_Grants!J5&"" | O5: =Access_Grants!K5&"" -> CHG-26704 | P5: =IF(OR(TRIM(N5)="",TRIM(O5)=""),"EXCEPTION: NO DOCUMENTED APPROVAL","OK - Approved") -> EXCEPTION: NO DOCUMENTED APPROVAL | Q5: =IFERROR(INDEX(SoD_Conflict_Matrix!$D$2:$D$7,MATCH(F5,SoD_Conflict_Matrix!$B$2:$B$7,0)),IFERROR(INDEX(SoD_Conflict_Matrix!$B$2:$B$7,MATCH(F5,SoD_Conflict_Matrix!$D$2:$D$7,0)),"")) | R5: =IFERROR(INDEX(SoD_Conflict_Matrix!$E$2:$E$7,MATCH(F5,SoD_Conflict_Matrix!$B$2:$B$7,0)),IFERROR(INDEX(SoD_Conflict_Matrix!$C$2:$C$7,MATCH(F5,SoD_Conflict_Matrix!$D$2:$D$7,0)),"")) | S5: =IF(Q5="","No Conflict Rule Applies to This Role",IF(COUNTIFS(Access_Grants!$B$2:$B$175,B5,Access_Grants!$F$2:$F$175,Q5,Access_Grants!$L$2:$L$175,"Active")>0,"EXCEPTION: SoD CONFLICT - ALSO HOLDS "&R5,"OK - No Conflicting Role Held")) -> No Conflict Rule Applies to This Role | T5: =IF(AND(H5="Admin",I5="Active"),IF(COUNTIFS(Recertifications!$B$2:$B$119,B5,Recertifications!$E$2:$E$119,F5,Recertifications!$K$2:$K$119,"<>")>0,"OK - Recertified","EXCEPTION: PRIVILEGED ACCESS NEVER RECERTIFIED"),"N/A - Not Privileged") -> N/A - Not Privileged | U5: =IF(OR(LEFT(M5,9)="EXCEPTION",LEFT(P5,9)="EXCEPTION",LEFT(S5,9)="EXCEPTION",LEFT(T5,9)="EXCEPTION"),"EXCEPTION","Clean") -> EXCEPTION | V5: =IF(LEFT(M5,9)="EXCEPTION","Deprovisioning Control Gap",IF(LEFT(S5,9)="EXCEPTION","Segregation of Duties Conflict",IF(LEFT(P5,9)="EXCEPTION","Provisioning Approval Gap",IF(LEFT(T5,9)="EXCEPTION","Recertification Gap","N/A")))) -> Provisioning Approval Gap
A6: =Access_Grants!A6 -> AG-0005 | B6: =Access_Grants!B6 -> E002 | C6: =Access_Grants!C6 -> Peter Okafor | D6: =Access_Grants!D6 -> HR | E6: =Access_Grants!E6 -> SYS-HRIS | F6: =Access_Grants!F6 -> R07 | G6: =Access_Grants!G6 -> Payroll Approval / Release | H6: =Access_Grants!H6 -> Admin | I6: =Access_Grants!L6 -> Active | J6: =Access_Grants!I6 -> 45018 | K6: =IFERROR(INDEX(HR_Employees!$F$2:$F$51,MATCH(B6,HR_Employees!$A$2:$A$51,0)),"") -> 45881 | L6: =IF(Access_Grants!M6="","",Access_Grants!M6) | M6: =IF(K6="","N/A - Active Employee",IF(OR(I6="Active",AND(L6<>"",L6>K6+5)),"EXCEPTION: TERMINATED USER - ACCESS NOT REVOKED TIMELY","OK - Revoked Within SLA")) -> EXCEPTION: TERMINATED USER - ACCESS NOT REVOKED TIMELY | N6: =Access_Grants!J6&"" -> MGR-04 | O6: =Access_Grants!K6&"" -> CHG-99399 | P6: =IF(OR(TRIM(N6)="",TRIM(O6)=""),"EXCEPTION: NO DOCUMENTED APPROVAL","OK - Approved") -> OK - Approved | Q6: =IFERROR(INDEX(SoD_Conflict_Matrix!$D$2:$D$7,MATCH(F6,SoD_Conflict_Matrix!$B$2:$B$7,0)),IFERROR(INDEX(SoD_Conflict_Matrix!$B$2:$B$7,MATCH(F6,SoD_Conflict_Matrix!$D$2:$D$7,0)),"")) -> R06 | R6: =IFERROR(INDEX(SoD_Conflict_Matrix!$E$2:$E$7,MATCH(F6,SoD_Conflict_Matrix!$B$2:$B$7,0)),IFERROR(INDEX(SoD_Conflict_Matrix!$C$2:$C$7,MATCH(F6,SoD_Conflict_Matrix!$D$2:$D$7,0)),"")) -> Payroll Data Entry | S6: =IF(Q6="","No Conflict Rule Applies to This Role",IF(COUNTIFS(Access_Grants!$B$2:$B$175,B6,Access_Grants!$F$2:$F$175,Q6,Access_Grants!$L$2:$L$175,"Active")>0,"EXCEPTION: SoD CONFLICT - ALSO HOLDS "&R6,"OK - No Conflicting Role Held")) -> OK - No Conflicting Role Held | T6: =IF(AND(H6="Admin",I6="Active"),IF(COUNTIFS(Recertifications!$B$2:$B$119,B6,Recertifications!$E$2:$E$119,F6,Recertifications!$K$2:$K$119,"<>")>0,"OK - Recertified","EXCEPTION: PRIVILEGED ACCESS NEVER RECERTIFIED"),"N/A - Not Privileged") -> OK - Recertified | U6: =IF(OR(LEFT(M6,9)="EXCEPTION",LEFT(P6,9)="EXCEPTION",LEFT(S6,9)="EXCEPTION",LEFT(T6,9)="EXCEPTION"),"EXCEPTION","Clean") -> EXCEPTION | V6: =IF(LEFT(M6,9)="EXCEPTION","Deprovisioning Control Gap",IF(LEFT(S6,9)="EXCEPTION","Segregation of Duties Conflict",IF(LEFT(P6,9)="EXCEPTION","Provisioning Approval Gap",IF(LEFT(T6,9)="EXCEPTION","Recertification Gap","N/A")))) -> Deprovisioning Control Gap
A7: =Access_Grants!A7 -> AG-0006 | B7: =Access_Grants!B7 -> E002 | C7: =Access_Grants!C7 -> Peter Okafor | D7: =Access_Grants!D7 -> HR | E7: =Access_Grants!E7 -> SYS-HRIS | F7: =Access_Grants!F7 -> R06 | G7: =Access_Grants!G7 -> Payroll Data Entry | H7: =Access_Grants!H7 -> Write | I7: =Access_Grants!L7 -> Revoked | J7: =Access_Grants!I7 -> 45070 | K7: =IFERROR(INDEX(HR_Employees!$F$2:$F$51,MATCH(B7,HR_Employees!$A$2:$A$51,0)),"") -> 45881 | L7: =IF(Access_Grants!M7="","",Access_Grants!M7) -> 45883 | M7: =IF(K7="","N/A - Active Employee",IF(OR(I7="Active",AND(L7<>"",L7>K7+5)),"EXCEPTION: TERMINATED USER - ACCESS NOT REVOKED TIMELY","OK - Revoked Within SLA")) -> OK - Revoked Within SLA | N7: =Access_Grants!J7&"" -> MGR-07 | O7: =Access_Grants!K7&"" -> CHG-91351 | P7: =IF(OR(TRIM(N7)="",TRIM(O7)=""),"EXCEPTION: NO DOCUMENTED APPROVAL","OK - Approved") -> OK - Approved | Q7: =IFERROR(INDEX(SoD_Conflict_Matrix!$D$2:$D$7,MATCH(F7,SoD_Conflict_Matrix!$B$2:$B$7,0)),IFERROR(INDEX(SoD_Conflict_Matrix!$B$2:$B$7,MATCH(F7,SoD_Conflict_Matrix!$D$2:$D$7,0)),"")) -> R07 | R7: =IFERROR(INDEX(SoD_Conflict_Matrix!$E$2:$E$7,MATCH(F7,SoD_Conflict_Matrix!$B$2:$B$7,0)),IFERROR(INDEX(SoD_Conflict_Matrix!$C$2:$C$7,MATCH(F7,SoD_Conflict_Matrix!$D$2:$D$7,0)),"")) -> Payroll Approval / Release | S7: =IF(Q7="","No Conflict Rule Applies to This Role",IF(COUNTIFS(Access_Grants!$B$2:$B$175,B7,Access_Grants!$F$2:$F$175,Q7,Access_Grants!$L$2:$L$175,"Active")>0,"EXCEPTION: SoD CONFLICT - ALSO HOLDS "&R7,"OK - No Conflicting Role Held")) -> EXCEPTION: SoD CONFLICT - ALSO HOLDS Payroll Approval / Release | T7: =IF(AND(H7="Admin",I7="Active"),IF(COUNTIFS(Recertifications!$B$2:$B$119,B7,Recertifications!$E$2:$E$119,F7,Recertifications!$K$2:$K$119,"<>")>0,"OK - Recertified","EXCEPTION: PRIVILEGED ACCESS NEVER RECERTIFIED"),"N/A - Not Privileged") -> N/A - Not Privileged | U7: =IF(OR(LEFT(M7,9)="EXCEPTION",LEFT(P7,9)="EXCEPTION",LEFT(S7,9)="EXCEPTION",LEFT(T7,9)="EXCEPTION"),"EXCEPTION","Clean") -> EXCEPTION | V7: =IF(LEFT(M7,9)="EXCEPTION","Deprovisioning Control Gap",IF(LEFT(S7,9)="EXCEPTION","Segregation of Duties Conflict",IF(LEFT(P7,9)="EXCEPTION","Provisioning Approval Gap",IF(LEFT(T7,9)="EXCEPTION","Recertification Gap","N/A")))) -> Segregation of Duties Conflict
A8: =Access_Grants!A8 -> AG-0007 | B8: =Access_Grants!B8 -> E002 | C8: =Access_Grants!C8 -> Peter Okafor | D8: =Access_Grants!D8 -> HR | E8: =Access_Grants!E8 -> SYS-HRIS | F8: =Access_Grants!F8 -> R08 | G8: =Access_Grants!G8 -> Employee Master Read-Only | H8: =Access_Grants!H8 -> Read | I8: =Access_Grants!L8 -> Active | J8: =Access_Grants!I8 -> 44968 | K8: =IFERROR(INDEX(HR_Employees!$F$2:$F$51,MATCH(B8,HR_Employees!$A$2:$A$51,0)),"") -> 45881 | L8: =IF(Access_Grants!M8="","",Access_Grants!M8) | M8: =IF(K8="","N/A - Active Employee",IF(OR(I8="Active",AND(L8<>"",L8>K8+5)),"EXCEPTION: TERMINATED USER - ACCESS NOT REVOKED TIMELY","OK - Revoked Within SLA")) -> EXCEPTION: TERMINATED USER - ACCESS NOT REVOKED TIMELY | N8: =Access_Grants!J8&"" -> MGR-03 | O8: =Access_Grants!K8&"" | P8: =IF(OR(TRIM(N8)="",TRIM(O8)=""),"EXCEPTION: NO DOCUMENTED APPROVAL","OK - Approved") -> EXCEPTION: NO DOCUMENTED APPROVAL | Q8: =IFERROR(INDEX(SoD_Conflict_Matrix!$D$2:$D$7,MATCH(F8,SoD_Conflict_Matrix!$B$2:$B$7,0)),IFERROR(INDEX(SoD_Conflict_Matrix!$B$2:$B$7,MATCH(F8,SoD_Conflict_Matrix!$D$2:$D$7,0)),"")) | R8: =IFERROR(INDEX(SoD_Conflict_Matrix!$E$2:$E$7,MATCH(F8,SoD_Conflict_Matrix!$B$2:$B$7,0)),IFERROR(INDEX(SoD_Conflict_Matrix!$C$2:$C$7,MATCH(F8,SoD_Conflict_Matrix!$D$2:$D$7,0)),"")) | S8: =IF(Q8="","No Conflict Rule Applies to This Role",IF(COUNTIFS(Access_Grants!$B$2:$B$175,B8,Access_Grants!$F$2:$F$175,Q8,Access_Grants!$L$2:$L$175,"Active")>0,"EXCEPTION: SoD CONFLICT - ALSO HOLDS "&R8,"OK - No Conflicting Role Held")) -> No Conflict Rule Applies to This Role | T8: =IF(AND(H8="Admin",I8="Active"),IF(COUNTIFS(Recertifications!$B$2:$B$119,B8,Recertifications!$E$2:$E$119,F8,Recertifications!$K$2:$K$119,"<>")>0,"OK - Recertified","EXCEPTION: PRIVILEGED ACCESS NEVER RECERTIFIED"),"N/A - Not Privileged") -> N/A - Not Privileged | U8: =IF(OR(LEFT(M8,9)="EXCEPTION",LEFT(P8,9)="EXCEPTION",LEFT(S8,9)="EXCEPTION",LEFT(T8,9)="EXCEPTION"),"EXCEPTION","Clean") -> EXCEPTION | V8: =IF(LEFT(M8,9)="EXCEPTION","Deprovisioning Control Gap",IF(LEFT(S8,9)="EXCEPTION","Segregation of Duties Conflict",IF(LEFT(P8,9)="EXCEPTION","Provisioning Approval Gap",IF(LEFT(T8,9)="EXCEPTION","Recertification Gap","N/A")))) -> Deprovisioning Control Gap
A9: =Access_Grants!A9 -> AG-0008 | B9: =Access_Grants!B9 -> E003 | C9: =Access_Grants!C9 -> Youssef Chen | D9: =Access_Grants!D9 -> Procurement | E9: =Access_Grants!E9 -> SYS-AD | F9: =Access_Grants!F9 -> R09 | G9: =Access_Grants!G9 -> Standard Network User | H9: =Access_Grants!H9 -> Read | I9: =Access_Grants!L9 -> Active | J9: =Access_Grants!I9 -> 45037 | K9: =IFERROR(INDEX(HR_Employees!$F$2:$F$51,MATCH(B9,HR_Employees!$A$2:$A$51,0)),"") -> 0 | L9: =IF(Access_Grants!M9="","",Access_Grants!M9) | M9: =IF(K9="","N/A - Active Employee",IF(OR(I9="Active",AND(L9<>"",L9>K9+5)),"EXCEPTION: TERMINATED USER - ACCESS NOT REVOKED TIMELY","OK - Revoked Within SLA")) -> N/A - Active Employee | N9: =Access_Grants!J9&"" -> MGR-07 | O9: =Access_Grants!K9&"" -> CHG-15075 | P9: =IF(OR(TRIM(N9)="",TRIM(O9)=""),"EXCEPTION: NO DOCUMENTED APPROVAL","OK - Approved") -> OK - Approved | Q9: =IFERROR(INDEX(SoD_Conflict_Matrix!$D$2:$D$7,MATCH(F9,SoD_Conflict_Matrix!$B$2:$B$7,0)),IFERROR(INDEX(SoD_Conflict_Matrix!$B$2:$B$7,MATCH(F9,SoD_Conflict_Matrix!$D$2:$D$7,0)),"")) | R9: =IFERROR(INDEX(SoD_Conflict_Matrix!$E$2:$E$7,MATCH(F9,SoD_Conflict_Matrix!$B$2:$B$7,0)),IFERROR(INDEX(SoD_Conflict_Matrix!$C$2:$C$7,MATCH(F9,SoD_Conflict_Matrix!$D$2:$D$7,0)),"")) | S9: =IF(Q9="","No Conflict Rule Applies to This Role",IF(COUNTIFS(Access_Grants!$B$2:$B$175,B9,Access_Grants!$F$2:$F$175,Q9,Access_Grants!$L$2:$L$175,"Active")>0,"EXCEPTION: SoD CONFLICT - ALSO HOLDS "&R9,"OK - No Conflicting Role Held")) -> No Conflict Rule Applies to This Role | T9: =IF(AND(H9="Admin",I9="Active"),IF(COUNTIFS(Recertifications!$B$2:$B$119,B9,Recertifications!$E$2:$E$119,F9,Recertifications!$K$2:$K$119,"<>")>0,"OK - Recertified","EXCEPTION: PRIVILEGED ACCESS NEVER RECERTIFIED"),"N/A - Not Privileged") -> N/A - Not Privileged | U9: =IF(OR(LEFT(M9,9)="EXCEPTION",LEFT(P9,9)="EXCEPTION",LEFT(S9,9)="EXCEPTION",LEFT(T9,9)="EXCEPTION"),"EXCEPTION","Clean") -> Clean | V9: =IF(LEFT(M9,9)="EXCEPTION","Deprovisioning Control Gap",IF(LEFT(S9,9)="EXCEPTION","Segregation of Duties Conflict",IF(LEFT(P9,9)="EXCEPTION","Provisioning Approval Gap",IF(LEFT(T9,9)="EXCEPTION","Recertification Gap","N/A")))) -> N/A
A10: =Access_Grants!A10 -> AG-0009 | B10: =Access_Grants!B10 -> E003 | C10: =Access_Grants!C10 -> Youssef Chen | D10: =Access_Grants!D10 -> Procurement | E10: =Access_Grants!E10 -> SYS-ERP | F10: =Access_Grants!F10 -> R03 | G10: =Access_Grants!G10 -> Vendor Master Maintenance | H10: =Access_Grants!H10 -> Write | I10: =Access_Grants!L10 -> Active | J10: =Access_Grants!I10 -> 45763 | K10: =IFERROR(INDEX(HR_Employees!$F$2:$F$51,MATCH(B10,HR_Employees!$A$2:$A$51,0)),"") -> 0 | L10: =IF(Access_Grants!M10="","",Access_Grants!M10) | M10: =IF(K10="","N/A - Active Employee",IF(OR(I10="Active",AND(L10<>"",L10>K10+5)),"EXCEPTION: TERMINATED USER - ACCESS NOT REVOKED TIMELY","OK - Revoked Within SLA")) -> N/A - Active Employee | N10: =Access_Grants!J10&"" -> MGR-08 | O10: =Access_Grants!K10&"" -> CHG-55830 | P10: =IF(OR(TRIM(N10)="",TRIM(O10)=""),"EXCEPTION: NO DOCUMENTED APPROVAL","OK - Approved") -> OK - Approved | Q10: =IFERROR(INDEX(SoD_Conflict_Matrix!$D$2:$D$7,MATCH(F10,SoD_Conflict_Matrix!$B$2:$B$7,0)),IFERROR(INDEX(SoD_Conflict_Matrix!$B$2:$B$7,MATCH(F10,SoD_Conflict_Matrix!$D$2:$D$7,0)),"")) -> R02 | R10: =IFERROR(INDEX(SoD_Conflict_Matrix!$E$2:$E$7,MATCH(F10,SoD_Conflict_Matrix!$B$2:$B$7,0)),IFERROR(INDEX(SoD_Conflict_Matrix!$C$2:$C$7,MATCH(F10,SoD_Conflict_Matrix!$D$2:$D$7,0)),"")) -> AP Payment Approval | S10: =IF(Q10="","No Conflict Rule Applies to This Role",IF(COUNTIFS(Access_Grants!$B$2:$B$175,B10,Access_Grants!$F$2:$F$175,Q10,Access_Grants!$L$2:$L$175,"Active")>0,"EXCEPTION: SoD CONFLICT - ALSO HOLDS "&R10,"OK - No Conflicting Role Held")) -> OK - No Conflicting Role Held | T10: =IF(AND(H10="Admin",I10="Active"),IF(COUNTIFS(Recertifications!$B$2:$B$119,B10,Recertifications!$E$2:$E$119,F10,Recertifications!$K$2:$K$119,"<>")>0,"OK - Recertified","EXCEPTION: PRIVILEGED ACCESS NEVER RECERTIFIED"),"N/A - Not Privileged") -> N/A - Not Privileged | U10: =IF(OR(LEFT(M10,9)="EXCEPTION",LEFT(P10,9)="EXCEPTION",LEFT(S10,9)="EXCEPTION",LEFT(T10,9)="EXCEPTION"),"EXCEPTION","Clean") -> Clean | V10: =IF(LEFT(M10,9)="EXCEPTION","Deprovisioning Control Gap",IF(LEFT(S10,9)="EXCEPTION","Segregation of Duties Conflict",IF(LEFT(P10,9)="EXCEPTION","Provisioning Approval Gap",IF(LEFT(T10,9)="EXCEPTION","Recertification Gap","N/A")))) -> N/A
A11: =Access_Grants!A11 -> AG-0010 | B11: =Access_Grants!B11 -> E003 | C11: =Access_Grants!C11 -> Youssef Chen | D11: =Access_Grants!D11 -> Procurement | E11: =Access_Grants!E11 -> SYS-ERP | F11: =Access_Grants!F11 -> R01 | G11: =Access_Grants!G11 -> AP Invoice Entry | H11: =Access_Grants!H11 -> Write | I11: =Access_Grants!L11 -> Active | J11: =Access_Grants!I11 -> 45160 | K11: =IFERROR(INDEX(HR_Employees!$F$2:$F$51,MATCH(B11,HR_Employees!$A$2:$A$51,0)),"") -> 0 | L11: =IF(Access_Grants!M11="","",Access_Grants!M11) | M11: =IF(K11="","N/A - Active Employee",IF(OR(I11="Active",AND(L11<>"",L11>K11+5)),"EXCEPTION: TERMINATED USER - ACCESS NOT REVOKED TIMELY","OK - Revoked Within SLA")) -> N/A - Active Employee | N11: =Access_Grants!J11&"" -> MGR-04 | O11: =Access_Grants!K11&"" -> CHG-13101 | P11: =IF(OR(TRIM(N11)="",TRIM(O11)=""),"EXCEPTION: NO DOCUMENTED APPROVAL","OK - Approved") -> OK - Approved | Q11: =IFERROR(INDEX(SoD_Conflict_Matrix!$D$2:$D$7,MATCH(F11,SoD_Conflict_Matrix!$B$2:$B$7,0)),IFERROR(INDEX(SoD_Conflict_Matrix!$B$2:$B$7,MATCH(F11,SoD_Conflict_Matrix!$D$2:$D$7,0)),"")) -> R02 | R11: =IFERROR(INDEX(SoD_Conflict_Matrix!$E$2:$E$7,MATCH(F11,SoD_Conflict_Matrix!$B$2:$B$7,0)),IFERROR(INDEX(SoD_Conflict_Matrix!$C$2:$C$7,MATCH(F11,SoD_Conflict_Matrix!$D$2:$D$7,0)),"")) -> AP Payment Approval | S11: =IF(Q11="","No Conflict Rule Applies to This Role",IF(COUNTIFS(Access_Grants!$B$2:$B$175,B11,Access_Grants!$F$2:$F$175,Q11,Access_Grants!$L$2:$L$175,"Active")>0,"EXCEPTION: SoD CONFLICT - ALSO HOLDS "&R11,"OK - No Conflicting Role Held")) -> OK - No Conflicting Role Held | T11: =IF(AND(H11="Admin",I11="Active"),IF(COUNTIFS(Recertifications!$B$2:$B$119,B11,Recertifications!$E$2:$E$119,F11,Recertifications!$K$2:$K$119,"<>")>0,"OK - Recertified","EXCEPTION: PRIVILEGED ACCESS NEVER RECERTIFIED"),"N/A - Not Privileged") -> N/A - Not Privileged | U11: =IF(OR(LEFT(M11,9)="EXCEPTION",LEFT(P11,9)="EXCEPTION",LEFT(S11,9)="EXCEPTION",LEFT(T11,9)="EXCEPTION"),"EXCEPTION","Clean") -> Clean | V11: =IF(LEFT(M11,9)="EXCEPTION","Deprovisioning Control Gap",IF(LEFT(S11,9)="EXCEPTION","Segregation of Duties Conflict",IF(LEFT(P11,9)="EXCEPTION","Provisioning Approval Gap",IF(LEFT(T11,9)="EXCEPTION","Recertification Gap","N/A")))) -> N/A
A12: =Access_Grants!A12 -> AG-0011 | B12: =Access_Grants!B12 -> E004 | C12: =Access_Grants!C12 -> Omar Khan | D12: =Access_Grants!D12 -> IT Operations | E12: =Access_Grants!E12 -> SYS-AD | F12: =Access_Grants!F12 -> R10 | G12: =Access_Grants!G12 -> Domain Administrator | H12: =Access_Grants!H12 -> Admin | I12: =Access_Grants!L12 -> Revoked | J12: =Access_Grants!I12 -> 44978 | K12: =IFERROR(INDEX(HR_Employees!$F$2:$F$51,MATCH(B12,HR_Employees!$A$2:$A$51,0)),"") -> 0 | L12: =IF(Access_Grants!M12="","",Access_Grants!M12) -> 45512 | M12: =IF(K12="","N/A - Active Employee",IF(OR(I12="Active",AND(L12<>"",L12>K12+5)),"EXCEPTION: TERMINATED USER - ACCESS NOT REVOKED TIMELY","OK - Revoked Within SLA")) -> N/A - Active Employee | N12: =Access_Grants!J12&"" -> System Auto-Provision | O12: =Access_Grants!K12&"" -> CHG-80282 | P12: =IF(OR(TRIM(N12)="",TRIM(O12)=""),"EXCEPTION: NO DOCUMENTED APPROVAL","OK - Approved") -> OK - Approved | Q12: =IFERROR(INDEX(SoD_Conflict_Matrix!$D$2:$D$7,MATCH(F12,SoD_Conflict_Matrix!$B$2:$B$7,0)),IFERROR(INDEX(SoD_Conflict_Matrix!$B$2:$B$7,MATCH(F12,SoD_Conflict_Matrix!$D$2:$D$7,0)),"")) | R12: =IFERROR(INDEX(SoD_Conflict_Matrix!$E$2:$E$7,MATCH(F12,SoD_Conflict_Matrix!$B$2:$B$7,0)),IFERROR(INDEX(SoD_Conflict_Matrix!$C$2:$C$7,MATCH(F12,SoD_Conflict_Matrix!$D$2:$D$7,0)),"")) | S12: =IF(Q12="","No Conflict Rule Applies to This Role",IF(COUNTIFS(Access_Grants!$B$2:$B$175,B12,Access_Grants!$F$2:$F$175,Q12,Access_Grants!$L$2:$L$175,"Active")>0,"EXCEPTION: SoD CONFLICT - ALSO HOLDS "&R12,"OK - No Conflicting Role Held")) -> No Conflict Rule Applies to This Role | T12: =IF(AND(H12="Admin",I12="Active"),IF(COUNTIFS(Recertifications!$B$2:$B$119,B12,Recertifications!$E$2:$E$119,F12,Recertifications!$K$2:$K$119,"<>")>0,"OK - Recertified","EXCEPTION: PRIVILEGED ACCESS NEVER RECERTIFIED"),"N/A - Not Privileged") -> N/A - Not Privileged | U12: =IF(OR(LEFT(M12,9)="EXCEPTION",LEFT(P12,9)="EXCEPTION",LEFT(S12,9)="EXCEPTION",LEFT(T12,9)="EXCEPTION"),"EXCEPTION","Clean") -> Clean | V12: =IF(LEFT(M12,9)="EXCEPTION","Deprovisioning Control Gap",IF(LEFT(S12,9)="EXCEPTION","Segregation of Duties Conflict",IF(LEFT(P12,9)="EXCEPTION","Provisioning Approval Gap",IF(LEFT(T12,9)="EXCEPTION","Recertification Gap","N/A")))) -> N/A
A13: =Access_Grants!A13 -> AG-0012 | B13: =Access_Grants!B13 -> E004 | C13: =Access_Grants!C13 -> Omar Khan | D13: =Access_Grants!D13 -> IT Operations | E13: =Access_Grants!E13 -> SYS-HRIS | F13: =Access_Grants!F13 -> R08 | G13: =Access_Grants!G13 -> Employee Master Read-Only | H13: =Access_Grants!H13 -> Read | I13: =Access_Grants!L13 -> Active | J13: =Access_Grants!I13 -> 44949 | K13: =IFERROR(INDEX(HR_Employees!$F$2:$F$51,MATCH(B13,HR_Employees!$A$2:$A$51,0)),"") -> 0 | L13: =IF(Access_Grants!M13="","",Access_Grants!M13) | M13: =IF(K13="","N/A - Active Employee",IF(OR(I13="Active",AND(L13<>"",L13>K13+5)),"EXCEPTION: TERMINATED USER - ACCESS NOT REVOKED TIMELY","OK - Revoked Within SLA")) -> N/A - Active Employee | N13: =Access_Grants!J13&"" -> MGR-10 | O13: =Access_Grants!K13&"" | P13: =IF(OR(TRIM(N13)="",TRIM(O13)=""),"EXCEPTION: NO DOCUMENTED APPROVAL","OK - Approved") -> EXCEPTION: NO DOCUMENTED APPROVAL | Q13: =IFERROR(INDEX(SoD_Conflict_Matrix!$D$2:$D$7,MATCH(F13,SoD_Conflict_Matrix!$B$2:$B$7,0)),IFERROR(INDEX(SoD_Conflict_Matrix!$B$2:$B$7,MATCH(F13,SoD_Conflict_Matrix!$D$2:$D$7,0)),"")) | R13: =IFERROR(INDEX(SoD_Conflict_Matrix!$E$2:$E$7,MATCH(F13,SoD_Conflict_Matrix!$B$2:$B$7,0)),IFERROR(INDEX(SoD_Conflict_Matrix!$C$2:$C$7,MATCH(F13,SoD_Conflict_Matrix!$D$2:$D$7,0)),"")) | S13: =IF(Q13="","No Conflict Rule Applies to This Role",IF(COUNTIFS(Access_Grants!$B$2:$B$175,B13,Access_Grants!$F$2:$F$175,Q13,Access_Grants!$L$2:$L$175,"Active")>0,"EXCEPTION: SoD CONFLICT - ALSO HOLDS "&R13,"OK - No Conflicting Role Held")) -> No Conflict Rule Applies to This Role | T13: =IF(AND(H13="Admin",I13="Active"),IF(COUNTIFS(Recertifications!$B$2:$B$119,B13,Recertifications!$E$2:$E$119,F13,Recertifications!$K$2:$K$119,"<>")>0,"OK - Recertified","EXCEPTION: PRIVILEGED ACCESS NEVER RECERTIFIED"),"N/A - Not Privileged") -> N/A - Not Privileged | U13: =IF(OR(LEFT(M13,9)="EXCEPTION",LEFT(P13,9)="EXCEPTION",LEFT(S13,9)="EXCEPTION",LEFT(T13,9)="EXCEPTION"),"EXCEPTION","Clean") -> EXCEPTION | V13: =IF(LEFT(M13,9)="EXCEPTION","Deprovisioning Control Gap",IF(LEFT(S13,9)="EXCEPTION","Segregation of Duties Conflict",IF(LEFT(P13,9)="EXCEPTION","Provisioning Approval Gap",IF(LEFT(T13,9)="EXCEPTION","Recertification Gap","N/A")))) -> Provisioning Approval Gap
